<?xml version="1.0"?>
<robot name="jetank">

  <!-- Base link -->
  <link name="base_link" />

  <joint name="base_joint" type="fixed">
    <parent link="base_link"/>
    <child link="chassis"/>
  </joint>

  <link name="chassis">
    <visual>
      <origin xyz="0 0 0.055"/>
      <geometry>
        <box size="0.2 0.1 0.08"/>
      </geometry>
    </visual>
    <collision>
      <origin xyz="0 0 0.055"/>
      <geometry>
        <box size="0.2 0.1 0.08"/>
      </geometry>
    </collision>
    <inertial>
      <mass value="1.0"/>
      <inertia ixx="0.1" ixy="0.0" ixz="0.0" iyy="0.1" iyz="0.0" izz="0.1"/>
    </inertial>
  </link>

  <!-- Wheels left -->
  <link name="wheel_left_front">
    <visual>
      <origin rpy="0 1.570 1.570" xyz="0.06 -0.0725 0.03"/>
      <geometry>
        <cylinder radius="0.03" length="0.05"/>
      </geometry>
    </visual>
    <collision>
      <origin rpy="0 1.570 1.570" xyz="0.06 -0.0725 0.03"/>
      <geometry>
        <cylinder radius="0.03" length="0.05"/>
      </geometry>
    </collision>
  </link>
  <link name="wheel_left_middle">
    <visual>
      <origin rpy="0 1.570 1.570" xyz="0.0 -0.0725 0.03"/>
      <geometry>
        <cylinder radius="0.03" length="0.05"/>
      </geometry>
    </visual>
    <collision>
      <origin rpy="0 1.570 1.570" xyz="0.0 -0.0725 0.03"/>
      <geometry>
        <cylinder radius="0.03" length="0.05"/>
      </geometry>
    </collision>
  </link>
  <link name="wheel_left_back">
    <visual>
      <origin rpy="0 1.570 1.570" xyz="-0.06 -0.0725 0.03"/>
      <geometry>
        <cylinder radius="0.03" length="0.05"/>
      </geometry>
    </visual>
    <collision>
      <origin rpy="0 1.570 1.570" xyz="-0.06 -0.0725 0.03"/>
      <geometry>
        <cylinder radius="0.03" length="0.05"/>
      </geometry>
    </collision>
  </link>

  <!-- Wheels right -->
  <link name="wheel_right_front">
    <visual>
      <origin rpy="0 1.570 1.570" xyz="0.06 0.0725 0.03"/>
      <geometry>
        <cylinder radius="0.03" length="0.05"/>
      </geometry>
    </visual>
    <collision>
      <origin rpy="0 1.570 1.570" xyz="0.06 0.0725 0.03"/>
      <geometry>
        <cylinder radius="0.03" length="0.05"/>
      </geometry>
    </collision>
  </link>
  <link name="wheel_right_middle">
    <visual>
      <origin rpy="0 1.570 1.570" xyz="0.0 0.0725 0.03"/>
      <geometry>
        <cylinder radius="0.03" length="0.05"/>
      </geometry>
    </visual>
    <collision>
      <origin rpy="0 1.570 1.570" xyz="0.0 0.0725 0.03"/>
      <geometry>
        <cylinder radius="0.03" length="0.05"/>
      </geometry>
    </collision>
  </link>
  <link name="wheel_right_back">
    <visual>
      <origin rpy="0 1.570 1.570" xyz="-0.06 0.0725 0.03"/>
      <geometry>
        <cylinder radius="0.03" length="0.05"/>
      </geometry>
    </visual>
    <collision>
      <origin rpy="0 1.570 1.570" xyz="-0.06 0.0725 0.03"/>
      <geometry>
        <cylinder radius="0.03" length="0.05"/>
      </geometry>
    </collision>
  </link>
  <!-- Joints - wheels left -->
  <joint name="wheel_left_front_joint" type="continuous">
    <parent link="chassis"/>
    <child link="wheel_left_front"/>
    <axis xyz="0 0 1"/>
  </joint>
  <joint name="wheel_left_middle_joint" type="continuous">
    <parent link="chassis"/>
    <child link="wheel_left_middle"/>
    <axis xyz="0 0 1"/>
  </joint>
  <joint name="wheel_left_back_joint" type="continuous">
    <parent link="chassis"/>
    <child link="wheel_left_back"/>
    <axis xyz="0 0 1"/>
  </joint>
  <!-- Joints - wheels right -->
  <joint name="wheel_right_front_joint" type="continuous">
    <parent link="chassis"/>
    <child link="wheel_right_front"/>
    <axis xyz="0 0 1"/>
  </joint>
  <joint name="wheel_right_middle_joint" type="continuous">
    <parent link="chassis"/>
    <child link="wheel_right_middle"/>
    <axis xyz="0 0 1"/>
  </joint>
  <joint name="wheel_right_back_joint" type="continuous">
    <parent link="chassis"/>
    <child link="wheel_right_back"/>
    <axis xyz="0 0 1"/>
  </joint>
</robot>
