<?xml version="1.0" encoding="utf-8" ?>
<!-- =================================================================================== -->
<!-- |    This document was autogenerated by xacro from /home/koen/workspaces/test/src/robot_main/urdf/jetank.xacro | -->
<!-- |    EDITING THIS FILE BY HAND IS NOT RECOMMENDED                                 | -->
<!-- =================================================================================== -->
<robot name="jetank">
    <!-- Links -->
    <!-- Bearing -->
    <link name="arm_bearing_link">
        <visual>
            <geometry>
                <cylinder length="0.01" radius="0.02" />
            </geometry>
        </visual>
    </link>
    <!-- Base Link -->
    <link name="arm_base_link">
        <visual>
            <geometry>
                <box size="0.07 0.045 0.075" />
            </geometry>
        </visual>
    </link>
    <!-- Camera Link -->
    <link name="arm_camera_link">
        <visual>
            <geometry>
                <box size="0.045 0.055 0.025" />
            </geometry>
            <origin rpy="0 0 0" xyz="0.0225 0 0" />
        </visual>
    </link>
    <!-- Long Link -->
    <link name="arm_long_link">
        <visual>
            <geometry>
                <box size="0.12 0.055 0.025" />
            </geometry>
            <origin rpy="0 0 0" xyz="0.06 0 0" />
        </visual>
    </link>
    <!-- Short Link -->
    <link name="arm_short_link">
        <visual>
            <geometry>
                <box size="0.09 0.045 0.02" />
            </geometry>
            <origin rpy="0 0 0" xyz="0.06 0 0" />
        </visual>
    </link>
    <!-- Joints -->
    <!-- Arm bearing to chassis -->
    <joint name="chassis_to_arm_bearing_joint" type="revolute">
        <parent link="chassis" />
        <child link="arm_bearing_link" />
        <origin rpy="0 0 0" xyz="0.045 0 0.045" />
        <axis xyz="0 0 1" />
        <limit effort="10.0" lower="-1.0" upper="1.0" velocity="1.0" />
    </joint>
    <!-- Arm base to arm bearing -->
    <joint name="arm_base_to_arm_bearing_joint" type="continuous">
        <parent link="arm_bearing_link" />
        <child link="arm_base_link" />
        <origin rpy="0 0 0" xyz="0.015 0 0.0425" />
        <axis xyz="0 0 1" />
    </joint>
    <!-- Camera to arm base joint -->
    <joint name="arm_base_to_camera_joint" type="revolute">
        <parent link="arm_base_link" />
        <child link="arm_camera_link" />
        <origin rpy="0 0 0" xyz="0.025 0 -0.0275" />
        <axis xyz="0 1 0" />
        <limit effort="10.0" lower="-1.0" upper="1.0" velocity="1.0" />
    </joint>
    <!-- Long link to arm base joint -->
    <joint name="arm_base_to_long_joint" type="revolute">
        <parent link="arm_base_link" />
        <child link="arm_long_link" />
        <origin rpy="0 -1.57079632679 0" xyz="-0.005 0 0.0275" />
        <axis xyz="0 1 0" />
        <limit effort="10.0" lower="-1.0" upper="1.0" velocity="1.0" />
    </joint>
    <!-- Short link to long link joint -->
    <joint name="arm_long_to_short_joint" type="revolute">
        <parent link="arm_long_link" />
        <child link="arm_short_link" />
        <origin rpy="0 1.57079632679 0" xyz="0.11 0 0" />
        <axis xyz="0 1 0" />
        <limit effort="10.0" lower="-1.0" upper="1.0" velocity="1.0" />
    </joint>
    <!-- Links -->
    <!-- Camera base -->
    <link name="gripper_base_link">
        <visual>
            <geometry>
                <box size="0.04 0.08 0.06" />
            </geometry>
        </visual>
    </link>
    <!-- Camera finger -->
    <!-- Joints -->
    <!-- Gripper base to arm -->
    <joint name="gripper_base_to_arm_joint" type="fixed">
        <parent link="arm_short_link" />
        <child link="gripper_base_link" />
        <origin rpy="0 0 0" xyz="0.11 0.01 0.03" />
    </joint>
    <link name="left_finger_link">
        <visual>
            <geometry>
                <box size="0.06 0.03 0.02" />
            </geometry>
        </visual>
    </link>
    <joint name="left_finger_joint" type="prismatic">
        <parent link="gripper_base_link" />
        <child link="left_finger_link" />
        <origin rpy="0 0 0" xyz="0.03 0.025 0" />
        <limit effort="10.0" lower="0" upper="0.02" velocity="1.0" />
        <axis xyz="0 -1 0" />
    </joint>
    <link name="right_finger_link">
        <visual>
            <geometry>
                <box size="0.06 0.03 0.02" />
            </geometry>
        </visual>
    </link>
    <joint name="right_finger_joint" type="prismatic">
        <parent link="gripper_base_link" />
        <child link="right_finger_link" />
        <origin rpy="0 0 0" xyz="0.03 -0.045 0" />
        <limit effort="10.0" lower="0" upper="0.02" velocity="1.0" />
        <axis xyz="0 1 0" />
        <mimic joint="left_finger_joint" multiplier="1.0" offset="0.0" />
    </joint>
    <!-- Base link -->
    <link name="base_link" />
    <!-- Main robot frame -->
    <link name="chassis">
        <visual>
            <!-- <origin xyz="0 0 ${ground_clearance+(chassis_height/2)}" /> -->
            <geometry>
                <box size="0.2 0.1 0.08" />
            </geometry>
        </visual>
        <collision>
            <!-- <origin xyz="0.0 0.0 ${(ground_clearance+(chassis_height/2))}"/> -->
            <geometry>
                <box size="0.2 0.1 0.08" />
            </geometry>
        </collision>
        
<inertial>
            <mass value="0.1" />
            <inertia ixx="0.03" iyy="0.03" izz="0.03" ixy="0.0" ixz="0.0" iyz="0.0" />
        </inertial>

    </link>
    <joint name="base_joint" type="fixed">
        <parent link="base_link" />
        <child link="chassis" />
        <origin xyz="0.0 0.0 0.05" />
    </joint>
    <link name="left_front_wheel">
        <visual>
            <origin rpy="0 1.57079632679 1.57079632679" xyz="0 0 0" />
            <geometry>
                <cylinder length="0.05" radius="0.03" />
            </geometry>
            <material name="black">
                <color rgba="0 0 0 1" />
            </material>
        </visual>
        <collision>
            <origin rpy="0 1.57079632679 1.57079632679" xyz="0 0 0" />
            <geometry>
                <cylinder length="0.05" radius="0.03" />
            </geometry>
        </collision>
        
<inertial>
            <mass value="0.1" />
            <inertia ixx="0.03" iyy="0.03" izz="0.03" ixy="0.0" ixz="0.0" iyz="0.0" />
        </inertial>

    </link>
    <joint name="left_front_wheel_joint" type="continuous">
        <parent link="chassis" />
        <child link="left_front_wheel" />
        <origin rpy="0 0 0" xyz="0.05 -0.075 -0.03" />
        <axis xyz="0 1 0" />
    </joint>
    <link name="right_front_wheel">
        <visual>
            <origin rpy="0 1.57079632679 1.57079632679" xyz="0 0 0" />
            <geometry>
                <cylinder length="0.05" radius="0.03" />
            </geometry>
            <material name="black">
                <color rgba="0 0 0 1" />
            </material>
        </visual>
        <collision>
            <origin rpy="0 1.57079632679 1.57079632679" xyz="0 0 0" />
            <geometry>
                <cylinder length="0.05" radius="0.03" />
            </geometry>
        </collision>
        
<inertial>
            <mass value="0.1" />
            <inertia ixx="0.03" iyy="0.03" izz="0.03" ixy="0.0" ixz="0.0" iyz="0.0" />
        </inertial>

    </link>
    <joint name="right_front_wheel_joint" type="continuous">
        <parent link="chassis" />
        <child link="right_front_wheel" />
        <origin rpy="0 0 0" xyz="0.05 0.075 -0.03" />
        <axis xyz="0 1 0" />
    </joint>
    <link name="left_middle_wheel">
        <visual>
            <origin rpy="0 1.57079632679 1.57079632679" xyz="0 0 0" />
            <geometry>
                <cylinder length="0.05" radius="0.03" />
            </geometry>
            <material name="black">
                <color rgba="0 0 0 1" />
            </material>
        </visual>
        <collision>
            <origin rpy="0 1.57079632679 1.57079632679" xyz="0 0 0" />
            <geometry>
                <cylinder length="0.05" radius="0.03" />
            </geometry>
        </collision>
        
<inertial>
            <mass value="0.1" />
            <inertia ixx="0.03" iyy="0.03" izz="0.03" ixy="0.0" ixz="0.0" iyz="0.0" />
        </inertial>

    </link>
    <joint name="left_middle_wheel_joint" type="continuous">
        <parent link="chassis" />
        <child link="left_middle_wheel" />
        <origin rpy="0 0 0" xyz="0 -0.075 -0.03" />
        <axis xyz="0 1 0" />
    </joint>
    <link name="right_middle_wheel">
        <visual>
            <origin rpy="0 1.57079632679 1.57079632679" xyz="0 0 0" />
            <geometry>
                <cylinder length="0.05" radius="0.03" />
            </geometry>
            <material name="black">
                <color rgba="0 0 0 1" />
            </material>
        </visual>
        <collision>
            <origin rpy="0 1.57079632679 1.57079632679" xyz="0 0 0" />
            <geometry>
                <cylinder length="0.05" radius="0.03" />
            </geometry>
        </collision>
        
<inertial>
            <mass value="0.1" />
            <inertia ixx="0.03" iyy="0.03" izz="0.03" ixy="0.0" ixz="0.0" iyz="0.0" />
        </inertial>

    </link>
    <joint name="right_middle_wheel_joint" type="continuous">
        <parent link="chassis" />
        <child link="right_middle_wheel" />
        <origin rpy="0 0 0" xyz="0 0.075 -0.03" />
        <axis xyz="0 1 0" />
    </joint>
    <link name="left_back_wheel">
        <visual>
            <origin rpy="0 1.57079632679 1.57079632679" xyz="0 0 0" />
            <geometry>
                <cylinder length="0.05" radius="0.03" />
            </geometry>
            <material name="black">
                <color rgba="0 0 0 1" />
            </material>
        </visual>
        <collision>
            <origin rpy="0 1.57079632679 1.57079632679" xyz="0 0 0" />
            <geometry>
                <cylinder length="0.05" radius="0.03" />
            </geometry>
        </collision>
        
<inertial>
            <mass value="0.1" />
            <inertia ixx="0.03" iyy="0.03" izz="0.03" ixy="0.0" ixz="0.0" iyz="0.0" />
        </inertial>

    </link>
    <joint name="left_back_wheel_joint" type="continuous">
        <parent link="chassis" />
        <child link="left_back_wheel" />
        <origin rpy="0 0 0" xyz="-0.05 -0.075 -0.03" />
        <axis xyz="0 1 0" />
    </joint>
    <link name="right_back_wheel">
        <visual>
            <origin rpy="0 1.57079632679 1.57079632679" xyz="0 0 0" />
            <geometry>
                <cylinder length="0.05" radius="0.03" />
            </geometry>
            <material name="black">
                <color rgba="0 0 0 1" />
            </material>
        </visual>
        <collision>
            <origin rpy="0 1.57079632679 1.57079632679" xyz="0 0 0" />
            <geometry>
                <cylinder length="0.05" radius="0.03" />
            </geometry>
        </collision>
        
<inertial>
            <mass value="0.1" />
            <inertia ixx="0.03" iyy="0.03" izz="0.03" ixy="0.0" ixz="0.0" iyz="0.0" />
        </inertial>

    </link>
    <joint name="right_back_wheel_joint" type="continuous">
        <parent link="chassis" />
        <child link="right_back_wheel" />
        <origin rpy="0 0 0" xyz="-0.05 0.075 -0.03" />
        <axis xyz="0 1 0" />
    </joint>
    
<transmission name="trans_chassis_to_arm_bearing_joint">
        <type>transmission_interface/SimpleTransmission</type>
        <joint name="chassis_to_arm_bearing_joint">
            <hardwareInterface>hardware_interface/EffortJointInterface</hardwareInterface>
        </joint>
        <actuator name="chassis_to_arm_bearing_joint_motor">
            <hardwareInterface>hardware_interface/EffortJointInterface</hardwareInterface>
            <mechanicalReduction>1</mechanicalReduction>
        </actuator>
    </transmission>
    <transmission name="trans_arm_base_to_arm_bearing_joint">
        <type>transmission_interface/SimpleTransmission</type>
        <joint name="arm_base_to_arm_bearing_joint">
            <hardwareInterface>hardware_interface/EffortJointInterface</hardwareInterface>
        </joint>
        <actuator name="arm_base_to_arm_bearing_joint_motor">
            <hardwareInterface>hardware_interface/EffortJointInterface</hardwareInterface>
            <mechanicalReduction>1</mechanicalReduction>
        </actuator>
    </transmission>
    <transmission name="trans_arm_base_to_camera_joint">
        <type>transmission_interface/SimpleTransmission</type>
        <joint name="arm_base_to_camera_joint">
            <hardwareInterface>hardware_interface/EffortJointInterface</hardwareInterface>
        </joint>
        <actuator name="arm_base_to_camera_joint_motor">
            <hardwareInterface>hardware_interface/EffortJointInterface</hardwareInterface>
            <mechanicalReduction>1</mechanicalReduction>
        </actuator>
    </transmission>
    <transmission name="trans_arm_base_to_long_joint">
        <type>transmission_interface/SimpleTransmission</type>
        <joint name="arm_base_to_long_joint">
            <hardwareInterface>hardware_interface/EffortJointInterface</hardwareInterface>
        </joint>
        <actuator name="arm_base_to_long_joint_motor">
            <hardwareInterface>hardware_interface/EffortJointInterface</hardwareInterface>
            <mechanicalReduction>1</mechanicalReduction>
        </actuator>
    </transmission>
    <transmission name="trans_arm_long_to_short_joint">
        <type>transmission_interface/SimpleTransmission</type>
        <joint name="arm_long_to_short_joint">
            <hardwareInterface>hardware_interface/EffortJointInterface</hardwareInterface>
        </joint>
        <actuator name="arm_long_to_short_joint_motor">
            <hardwareInterface>hardware_interface/EffortJointInterface</hardwareInterface>
            <mechanicalReduction>1</mechanicalReduction>
        </actuator>
    </transmission>
    <transmission name="trans_left_finger_joint">
        <type>transmission_interface/SimpleTransmission</type>
        <joint name="left_finger_joint">
            <hardwareInterface>hardware_interface/EffortJointInterface</hardwareInterface>
        </joint>
        <actuator name="left_finger_joint_motor">
            <hardwareInterface>hardware_interface/EffortJointInterface</hardwareInterface>
            <mechanicalReduction>1</mechanicalReduction>
        </actuator>
    </transmission>
    <transmission name="trans_right_finger_joint">
        <type>transmission_interface/SimpleTransmission</type>
        <joint name="right_finger_joint">
            <hardwareInterface>hardware_interface/EffortJointInterface</hardwareInterface>
        </joint>
        <actuator name="right_finger_joint_motor">
            <hardwareInterface>hardware_interface/EffortJointInterface</hardwareInterface>
            <mechanicalReduction>1</mechanicalReduction>
        </actuator>
    </transmission>
    <transmission name="trans_left_front_wheel_joint">
        <type>transmission_interface/SimpleTransmission</type>
        <joint name="left_front_wheel_joint">
            <hardwareInterface>hardware_interface/EffortJointInterface</hardwareInterface>
        </joint>
        <actuator name="left_front_wheel_joint_motor">
            <hardwareInterface>hardware_interface/EffortJointInterface</hardwareInterface>
            <mechanicalReduction>1</mechanicalReduction>
        </actuator>
    </transmission>
    <transmission name="trans_right_front_wheel_joint">
        <type>transmission_interface/SimpleTransmission</type>
        <joint name="right_front_wheel_joint">
            <hardwareInterface>hardware_interface/EffortJointInterface</hardwareInterface>
        </joint>
        <actuator name="right_front_wheel_joint_motor">
            <hardwareInterface>hardware_interface/EffortJointInterface</hardwareInterface>
            <mechanicalReduction>1</mechanicalReduction>
        </actuator>
    </transmission>
    <transmission name="trans_left_middle_wheel_joint">
        <type>transmission_interface/SimpleTransmission</type>
        <joint name="left_middle_wheel_joint">
            <hardwareInterface>hardware_interface/EffortJointInterface</hardwareInterface>
        </joint>
        <actuator name="left_middle_wheel_joint_motor">
            <hardwareInterface>hardware_interface/EffortJointInterface</hardwareInterface>
            <mechanicalReduction>1</mechanicalReduction>
        </actuator>
    </transmission>
    <transmission name="trans_right_middle_wheel_joint">
        <type>transmission_interface/SimpleTransmission</type>
        <joint name="right_middle_wheel_joint">
            <hardwareInterface>hardware_interface/EffortJointInterface</hardwareInterface>
        </joint>
        <actuator name="right_middle_wheel_joint_motor">
            <hardwareInterface>hardware_interface/EffortJointInterface</hardwareInterface>
            <mechanicalReduction>1</mechanicalReduction>
        </actuator>
    </transmission>
    <transmission name="trans_left_back_wheel_joint">
        <type>transmission_interface/SimpleTransmission</type>
        <joint name="left_back_wheel_joint">
            <hardwareInterface>hardware_interface/EffortJointInterface</hardwareInterface>
        </joint>
        <actuator name="left_back_wheel_joint_motor">
            <hardwareInterface>hardware_interface/EffortJointInterface</hardwareInterface>
            <mechanicalReduction>1</mechanicalReduction>
        </actuator>
    </transmission>
    <transmission name="trans_right_back_wheel_joint">
        <type>transmission_interface/SimpleTransmission</type>
        <joint name="right_back_wheel_joint">
            <hardwareInterface>hardware_interface/EffortJointInterface</hardwareInterface>
        </joint>
        <actuator name="right_back_wheel_joint_motor">
            <hardwareInterface>hardware_interface/EffortJointInterface</hardwareInterface>
            <mechanicalReduction>1</mechanicalReduction>
        </actuator>
    </transmission>
    <gazebo>
        <plugin name="gazebo_ros_control" filename="libgazebo_ros_control.so">
            <robotNamespace>/</robotNamespace>
        </plugin>
    </gazebo>